2023-05-12 11:58:47,543 INFO    Thread-9 (_run_job):898703 [wandb_setup.py:_flush():76] Configure stats pid to 898703
2023-05-12 11:58:47,543 INFO    Thread-9 (_run_job):898703 [wandb_setup.py:_flush():76] Loading settings from /home/abdullah/.config/wandb/settings
2023-05-12 11:58:47,543 INFO    Thread-9 (_run_job):898703 [wandb_setup.py:_flush():76] Loading settings from /home/abdullah/Desktop/Courses/Sem6/CS6910/A3/wandb/settings
2023-05-12 11:58:47,543 INFO    Thread-9 (_run_job):898703 [wandb_setup.py:_flush():76] Loading settings from environment variables: {'project': 'hyperparam-search-seq2seq', 'entity': 'abdullah_010', 'root_dir': '/home/abdullah/Desktop/Courses/Sem6/CS6910/A3', 'run_id': 'eru7a1ln', 'sweep_param_path': '/home/abdullah/Desktop/Courses/Sem6/CS6910/A3/wandb/sweep-eq24qohr/config-eru7a1ln.yaml', 'sweep_id': 'eq24qohr'}
2023-05-12 11:58:47,543 INFO    Thread-9 (_run_job):898703 [wandb_setup.py:_flush():76] Applying setup settings: {'_disable_service': False}
2023-05-12 11:58:47,543 INFO    Thread-9 (_run_job):898703 [wandb_setup.py:_flush():76] Inferring run settings from compute environment: {'program': '<python with no main file>'}
2023-05-12 11:58:47,543 INFO    Thread-9 (_run_job):898703 [wandb_init.py:_log_setup():506] Logging user logs to /home/abdullah/Desktop/Courses/Sem6/CS6910/A3/wandb/run-20230512_115847-eru7a1ln/logs/debug.log
2023-05-12 11:58:47,543 INFO    Thread-9 (_run_job):898703 [wandb_init.py:_log_setup():507] Logging internal logs to /home/abdullah/Desktop/Courses/Sem6/CS6910/A3/wandb/run-20230512_115847-eru7a1ln/logs/debug-internal.log
2023-05-12 11:58:47,544 INFO    Thread-9 (_run_job):898703 [wandb_init.py:_jupyter_setup():452] configuring jupyter hooks <wandb.sdk.wandb_init._WandbInit object at 0x7f09948a7be0>
2023-05-12 11:58:47,544 INFO    Thread-9 (_run_job):898703 [wandb_init.py:init():546] calling init triggers
2023-05-12 11:58:47,544 INFO    Thread-9 (_run_job):898703 [wandb_init.py:init():552] wandb.init called with sweep_config: {'beam_width': 1, 'cell_type': 'gru', 'dropout': 0.2, 'embedding_size': 64, 'epochs': 10, 'hidden_layer_size': 128, 'learning_rate': 0.005, 'num_hidden_layers': 3, 'optimizer': 'SGD'}
config: {}
2023-05-12 11:58:47,544 INFO    Thread-9 (_run_job):898703 [wandb_init.py:init():602] starting backend
2023-05-12 11:58:47,544 INFO    Thread-9 (_run_job):898703 [wandb_init.py:init():606] setting up manager
2023-05-12 11:58:47,548 INFO    Thread-9 (_run_job):898703 [backend.py:_multiprocessing_setup():106] multiprocessing start_methods=fork,spawn,forkserver, using: spawn
2023-05-12 11:58:47,551 INFO    Thread-9 (_run_job):898703 [wandb_init.py:init():613] backend started and connected
2023-05-12 11:58:47,566 INFO    Thread-9 (_run_job):898703 [wandb_run.py:_config_callback():1249] config_cb None None {'beam_width': 1, 'cell_type': 'gru', 'dropout': 0.2, 'embedding_size': 64, 'epochs': 10, 'hidden_layer_size': 128, 'learning_rate': 0.005, 'num_hidden_layers': 3, 'optimizer': 'SGD'}
2023-05-12 11:58:47,566 INFO    Thread-9 (_run_job):898703 [wandb_run.py:_label_probe_notebook():1202] probe notebook
2023-05-12 11:58:47,566 INFO    Thread-9 (_run_job):898703 [wandb_run.py:_label_probe_notebook():1212] Unable to probe notebook: 'NoneType' object has no attribute 'get'
2023-05-12 11:58:47,566 INFO    Thread-9 (_run_job):898703 [wandb_init.py:init():701] updated telemetry
2023-05-12 11:58:47,570 INFO    Thread-9 (_run_job):898703 [wandb_init.py:init():741] communicating run to backend with 60.0 second timeout
2023-05-12 11:58:48,458 INFO    Thread-9 (_run_job):898703 [wandb_run.py:_on_init():2131] communicating current version
2023-05-12 11:58:48,592 INFO    Thread-9 (_run_job):898703 [wandb_run.py:_on_init():2140] got version response upgrade_message: "wandb version 0.15.2 is available!  To upgrade, please run:\n $ pip install wandb --upgrade"

2023-05-12 11:58:48,592 INFO    Thread-9 (_run_job):898703 [wandb_init.py:init():789] starting run threads in backend
2023-05-12 11:58:51,607 INFO    Thread-9 (_run_job):898703 [wandb_run.py:_console_start():2112] atexit reg
2023-05-12 11:58:51,607 INFO    Thread-9 (_run_job):898703 [wandb_run.py:_redirect():1967] redirect: SettingsConsole.WRAP_RAW
2023-05-12 11:58:51,607 INFO    Thread-9 (_run_job):898703 [wandb_run.py:_redirect():2032] Wrapping output streams.
2023-05-12 11:58:51,607 INFO    Thread-9 (_run_job):898703 [wandb_run.py:_redirect():2057] Redirects installed.
2023-05-12 11:58:51,607 INFO    Thread-9 (_run_job):898703 [wandb_init.py:init():831] run started, returning control to user process
2023-05-12 12:21:52,237 INFO    Thread-4 (_heartbeat):898703 [retry.py:__call__():172] Retry attempt failed:
Traceback (most recent call last):
  File "/home/abdullah/.local/lib/python3.10/site-packages/urllib3/connection.py", line 174, in _new_conn
    conn = connection.create_connection(
  File "/home/abdullah/.local/lib/python3.10/site-packages/urllib3/util/connection.py", line 72, in create_connection
    for res in socket.getaddrinfo(host, port, family, socket.SOCK_STREAM):
  File "/usr/lib/python3.10/socket.py", line 955, in getaddrinfo
    for res in _socket.getaddrinfo(host, port, family, type, proto, flags):
socket.gaierror: [Errno -3] Temporary failure in name resolution

During handling of the above exception, another exception occurred:

Traceback (most recent call last):
  File "/home/abdullah/.local/lib/python3.10/site-packages/urllib3/connectionpool.py", line 703, in urlopen
    httplib_response = self._make_request(
  File "/home/abdullah/.local/lib/python3.10/site-packages/urllib3/connectionpool.py", line 386, in _make_request
    self._validate_conn(conn)
  File "/home/abdullah/.local/lib/python3.10/site-packages/urllib3/connectionpool.py", line 1042, in _validate_conn
    conn.connect()
  File "/home/abdullah/.local/lib/python3.10/site-packages/urllib3/connection.py", line 358, in connect
    self.sock = conn = self._new_conn()
  File "/home/abdullah/.local/lib/python3.10/site-packages/urllib3/connection.py", line 186, in _new_conn
    raise NewConnectionError(
urllib3.exceptions.NewConnectionError: <urllib3.connection.HTTPSConnection object at 0x7f0995b0e8f0>: Failed to establish a new connection: [Errno -3] Temporary failure in name resolution

During handling of the above exception, another exception occurred:

Traceback (most recent call last):
  File "/home/abdullah/.local/lib/python3.10/site-packages/requests/adapters.py", line 489, in send
    resp = conn.urlopen(
  File "/home/abdullah/.local/lib/python3.10/site-packages/urllib3/connectionpool.py", line 787, in urlopen
    retries = retries.increment(
  File "/home/abdullah/.local/lib/python3.10/site-packages/urllib3/util/retry.py", line 592, in increment
    raise MaxRetryError(_pool, url, error or ResponseError(cause))
urllib3.exceptions.MaxRetryError: HTTPSConnectionPool(host='api.wandb.ai', port=443): Max retries exceeded with url: /graphql (Caused by NewConnectionError('<urllib3.connection.HTTPSConnection object at 0x7f0995b0e8f0>: Failed to establish a new connection: [Errno -3] Temporary failure in name resolution'))

During handling of the above exception, another exception occurred:

Traceback (most recent call last):
  File "/home/abdullah/.local/lib/python3.10/site-packages/wandb/sdk/lib/retry.py", line 131, in __call__
    result = self._call_fn(*args, **kwargs)
  File "/home/abdullah/.local/lib/python3.10/site-packages/wandb/sdk/internal/internal_api.py", line 242, in execute
    return self.client.execute(*args, **kwargs)  # type: ignore
  File "/home/abdullah/.local/lib/python3.10/site-packages/wandb/vendor/gql-0.2.0/wandb_gql/client.py", line 52, in execute
    result = self._get_result(document, *args, **kwargs)
  File "/home/abdullah/.local/lib/python3.10/site-packages/wandb/vendor/gql-0.2.0/wandb_gql/client.py", line 60, in _get_result
    return self.transport.execute(document, *args, **kwargs)
  File "/home/abdullah/.local/lib/python3.10/site-packages/wandb/vendor/gql-0.2.0/wandb_gql/transport/requests.py", line 38, in execute
    request = requests.post(self.url, **post_args)
  File "/home/abdullah/.local/lib/python3.10/site-packages/requests/api.py", line 115, in post
    return request("post", url, data=data, json=json, **kwargs)
  File "/home/abdullah/.local/lib/python3.10/site-packages/requests/api.py", line 59, in request
    return session.request(method=method, url=url, **kwargs)
  File "/home/abdullah/.local/lib/python3.10/site-packages/requests/sessions.py", line 587, in request
    resp = self.send(prep, **send_kwargs)
  File "/home/abdullah/.local/lib/python3.10/site-packages/requests/sessions.py", line 701, in send
    r = adapter.send(request, **kwargs)
  File "/home/abdullah/.local/lib/python3.10/site-packages/requests/adapters.py", line 565, in send
    raise ConnectionError(e, request=request)
requests.exceptions.ConnectionError: HTTPSConnectionPool(host='api.wandb.ai', port=443): Max retries exceeded with url: /graphql (Caused by NewConnectionError('<urllib3.connection.HTTPSConnection object at 0x7f0995b0e8f0>: Failed to establish a new connection: [Errno -3] Temporary failure in name resolution'))
2023-05-12 12:42:33,397 INFO    Thread-9 (_run_job):898703 [wandb_run.py:_finish():1852] finishing run abdullah_010/hyperparam-search-seq2seq/eru7a1ln
2023-05-12 12:42:33,397 INFO    Thread-9 (_run_job):898703 [jupyter.py:save_history():445] not saving jupyter history
2023-05-12 12:42:33,397 INFO    Thread-9 (_run_job):898703 [jupyter.py:save_ipynb():373] not saving jupyter notebook
2023-05-12 12:42:33,397 INFO    Thread-9 (_run_job):898703 [wandb_init.py:_jupyter_teardown():434] cleaning up jupyter logic
2023-05-12 12:42:33,397 INFO    Thread-9 (_run_job):898703 [wandb_run.py:_atexit_cleanup():2081] got exitcode: 0
2023-05-12 12:42:33,397 INFO    Thread-9 (_run_job):898703 [wandb_run.py:_restore():2064] restore
2023-05-12 12:42:33,397 INFO    Thread-9 (_run_job):898703 [wandb_run.py:_restore():2070] restore done
2023-05-12 12:42:44,741 INFO    Thread-9 (_run_job):898703 [wandb_run.py:_footer_history_summary_info():3429] rendering history
2023-05-12 12:42:44,742 INFO    Thread-9 (_run_job):898703 [wandb_run.py:_footer_history_summary_info():3461] rendering summary
2023-05-12 12:42:44,744 INFO    Thread-9 (_run_job):898703 [wandb_run.py:_footer_sync_info():3387] logging synced files
